<?xml version="1.0"?>
<robot name="w2robot">

<material name="blue">
    <color rgba="0 0 0.8 1"/>
</material>

<material name="black">
    <color rgba="0 0 0 1"/>
</material>

<material name="white">
    <color rgba="1 1 1 1"/>
</material>

<link name="base_link">
    <visual>
        <geometry>
            <box size="0.4 0.2 0.1"/>
        </geometry>
        <origin rpy="0 0 0" xyz="0 0 0.1" />
        <material name="blue"/>
    </visual>
    <collision>
        <geometry>
            <box size="0.4 0.2 0.1"/>
        </geometry>
    </collision>
    <inertial>
        <mass value="10"/>
        <inertia ixx="1e-3" ixy="0.0" ixz="0.0" iyy="1e-3" iyz="0.0" izz="1e-3"/>
    </inertial>
</link>

<link name="right_wheel">
    <visual>
        <geometry>
        <cylinder radius="0.1" length="0.05"/>
        </geometry>
        <origin xyz="0 0 0" rpy="0 0 0"/>
        <material name="white"/>
    </visual>
</link>

<joint name="right_wheel_hinge" type="continuous">
    <axis rpy="0 0 0" xyz="0 0 -1"/>
    <parent link="base_link"/>
    <child link="right_wheel"/>
    <origin xyz="0.1 -0.13 0.1" rpy="0 1.5707 1.5707"/>
</joint>

<link name="left_wheel">
    <visual>
        <geometry>
            <cylinder radius="0.1" length="0.05"/>
        </geometry>
        <origin xyz="0 0 0" rpy="0 0 0"/>
        <material name="white"/>
    </visual>
</link>

<joint name="left_wheel_hinge" type="continuous">
    <axis rpy="0 0 0" xyz="0 0 1"/>
    <parent link="base_link"/>
    <child link="left_wheel"/>
    <origin xyz="0.1 0.13 0.1" rpy="1.5707 1.5707 0"/>
</joint>

<link name="caster_wheel">
    <visual>
        <geometry>
            <sphere radius="0.05"/>
        </geometry>
        <origin xyz="0 0 0" rpy="0 0 0"/>
        <material name="white"/>
    </visual>
</link>

<joint name="caster_hinge" type="fixed">
    <axis rpy="0 0 0" xyz="0 1 0"/>
    <parent link="base_link"/>
    <child link="caster_wheel"/>
    <origin xyz="-0.15 0 0.05" rpy="0 0 0"/>
</joint>

</robot>